2023-04-26 13:41:49,116 ERROR: Exception on /contacts [GET] [in /Users/lusarsfield/Code/ContactedWebApp/venv/lib/python3.10/site-packages/flask/app.py:1744]
Traceback (most recent call last):
  File "/Users/lusarsfield/Code/ContactedWebApp/venv/lib/python3.10/site-packages/flask/app.py", line 2528, in wsgi_app
    response = self.full_dispatch_request()
  File "/Users/lusarsfield/Code/ContactedWebApp/venv/lib/python3.10/site-packages/flask/app.py", line 1825, in full_dispatch_request
    rv = self.handle_user_exception(e)
  File "/Users/lusarsfield/Code/ContactedWebApp/venv/lib/python3.10/site-packages/flask/app.py", line 1823, in full_dispatch_request
    rv = self.dispatch_request()
  File "/Users/lusarsfield/Code/ContactedWebApp/venv/lib/python3.10/site-packages/flask/app.py", line 1799, in dispatch_request
    return self.ensure_sync(self.view_functions[rule.endpoint])(**view_args)
  File "/Users/lusarsfield/Code/ContactedWebApp/venv/lib/python3.10/site-packages/flask_login/utils.py", line 290, in decorated_view
    return current_app.ensure_sync(func)(*args, **kwargs)
  File "/Users/lusarsfield/Code/ContactedWebApp/app/routes.py", line 213, in contacts
    c.execute('select name from people')
sqlite3.OperationalError: no such table: people
2023-04-26 13:42:45,093 INFO: Microblog startup [in /Users/lusarsfield/Code/ContactedWebApp/app/__init__.py:47]
2023-04-26 13:42:46,971 ERROR: Exception on /contacts [GET] [in /Users/lusarsfield/Code/ContactedWebApp/venv/lib/python3.10/site-packages/flask/app.py:1744]
Traceback (most recent call last):
  File "/Users/lusarsfield/Code/ContactedWebApp/venv/lib/python3.10/site-packages/flask/app.py", line 2528, in wsgi_app
    response = self.full_dispatch_request()
  File "/Users/lusarsfield/Code/ContactedWebApp/venv/lib/python3.10/site-packages/flask/app.py", line 1825, in full_dispatch_request
    rv = self.handle_user_exception(e)
  File "/Users/lusarsfield/Code/ContactedWebApp/venv/lib/python3.10/site-packages/flask/app.py", line 1823, in full_dispatch_request
    rv = self.dispatch_request()
  File "/Users/lusarsfield/Code/ContactedWebApp/venv/lib/python3.10/site-packages/flask/app.py", line 1799, in dispatch_request
    return self.ensure_sync(self.view_functions[rule.endpoint])(**view_args)
  File "/Users/lusarsfield/Code/ContactedWebApp/venv/lib/python3.10/site-packages/flask_login/utils.py", line 290, in decorated_view
    return current_app.ensure_sync(func)(*args, **kwargs)
  File "/Users/lusarsfield/Code/ContactedWebApp/app/routes.py", line 213, in contacts
    c.execute('SELECT name FROM people')
sqlite3.OperationalError: no such table: people
2023-04-26 13:42:48,356 ERROR: Exception on /contacts [GET] [in /Users/lusarsfield/Code/ContactedWebApp/venv/lib/python3.10/site-packages/flask/app.py:1744]
Traceback (most recent call last):
  File "/Users/lusarsfield/Code/ContactedWebApp/venv/lib/python3.10/site-packages/flask/app.py", line 2528, in wsgi_app
    response = self.full_dispatch_request()
  File "/Users/lusarsfield/Code/ContactedWebApp/venv/lib/python3.10/site-packages/flask/app.py", line 1825, in full_dispatch_request
    rv = self.handle_user_exception(e)
  File "/Users/lusarsfield/Code/ContactedWebApp/venv/lib/python3.10/site-packages/flask/app.py", line 1823, in full_dispatch_request
    rv = self.dispatch_request()
  File "/Users/lusarsfield/Code/ContactedWebApp/venv/lib/python3.10/site-packages/flask/app.py", line 1799, in dispatch_request
    return self.ensure_sync(self.view_functions[rule.endpoint])(**view_args)
  File "/Users/lusarsfield/Code/ContactedWebApp/venv/lib/python3.10/site-packages/flask_login/utils.py", line 290, in decorated_view
    return current_app.ensure_sync(func)(*args, **kwargs)
  File "/Users/lusarsfield/Code/ContactedWebApp/app/routes.py", line 213, in contacts
    c.execute('SELECT name FROM people')
sqlite3.OperationalError: no such table: people
2023-04-26 13:48:49,225 INFO: Microblog startup [in /Users/lusarsfield/Code/ContactedWebApp/app/__init__.py:47]
2023-04-26 13:49:22,692 INFO: Microblog startup [in /Users/lusarsfield/Code/ContactedWebApp/app/__init__.py:47]
2023-04-26 13:50:15,025 INFO: Microblog startup [in /Users/lusarsfield/Code/ContactedWebApp/app/__init__.py:47]
2023-04-26 13:52:40,648 INFO: Microblog startup [in /Users/lusarsfield/Code/ContactedWebApp/app/__init__.py:47]
2023-04-26 13:57:49,931 INFO: Microblog startup [in /Users/lusarsfield/Code/ContactedWebApp/app/__init__.py:47]
2023-04-26 13:58:04,034 INFO: Microblog startup [in /Users/lusarsfield/Code/ContactedWebApp/app/__init__.py:47]
2023-04-26 13:58:16,145 INFO: Microblog startup [in /Users/lusarsfield/Code/ContactedWebApp/app/__init__.py:47]
2023-04-26 14:02:18,374 INFO: Microblog startup [in /Users/lusarsfield/Code/ContactedWebApp/app/__init__.py:47]
2023-04-26 14:02:25,067 ERROR: Exception on /contacts [GET] [in /Users/lusarsfield/Code/ContactedWebApp/venv/lib/python3.10/site-packages/flask/app.py:1744]
Traceback (most recent call last):
  File "/Users/lusarsfield/Code/ContactedWebApp/venv/lib/python3.10/site-packages/flask/app.py", line 2528, in wsgi_app
    response = self.full_dispatch_request()
  File "/Users/lusarsfield/Code/ContactedWebApp/venv/lib/python3.10/site-packages/flask/app.py", line 1825, in full_dispatch_request
    rv = self.handle_user_exception(e)
  File "/Users/lusarsfield/Code/ContactedWebApp/venv/lib/python3.10/site-packages/flask/app.py", line 1823, in full_dispatch_request
    rv = self.dispatch_request()
  File "/Users/lusarsfield/Code/ContactedWebApp/venv/lib/python3.10/site-packages/flask/app.py", line 1799, in dispatch_request
    return self.ensure_sync(self.view_functions[rule.endpoint])(**view_args)
  File "/Users/lusarsfield/Code/ContactedWebApp/venv/lib/python3.10/site-packages/flask_login/utils.py", line 290, in decorated_view
    return current_app.ensure_sync(func)(*args, **kwargs)
  File "/Users/lusarsfield/Code/ContactedWebApp/app/routes.py", line 211, in contacts
    return render_template('contacts.html', title='Contacts')
  File "/Users/lusarsfield/Code/ContactedWebApp/venv/lib/python3.10/site-packages/flask/templating.py", line 147, in render_template
    return _render(app, template, context)
  File "/Users/lusarsfield/Code/ContactedWebApp/venv/lib/python3.10/site-packages/flask/templating.py", line 130, in _render
    rv = template.render(context)
  File "/Users/lusarsfield/Code/ContactedWebApp/venv/lib/python3.10/site-packages/jinja2/environment.py", line 1301, in render
    self.environment.handle_exception()
  File "/Users/lusarsfield/Code/ContactedWebApp/venv/lib/python3.10/site-packages/jinja2/environment.py", line 936, in handle_exception
    raise rewrite_traceback_stack(source=source)
  File "/Users/lusarsfield/Code/ContactedWebApp/app/templates/contacts.html", line 2, in top-level template code
    {% import 'bootstrap/wtf.html' as wtf %}
jinja2.exceptions.TemplateRuntimeError: extended multiple times
2023-04-26 14:03:17,200 INFO: Microblog startup [in /Users/lusarsfield/Code/ContactedWebApp/app/__init__.py:47]
2023-04-26 14:03:19,169 ERROR: Exception on /contacts [GET] [in /Users/lusarsfield/Code/ContactedWebApp/venv/lib/python3.10/site-packages/flask/app.py:1744]
Traceback (most recent call last):
  File "/Users/lusarsfield/Code/ContactedWebApp/venv/lib/python3.10/site-packages/flask/app.py", line 2528, in wsgi_app
    response = self.full_dispatch_request()
  File "/Users/lusarsfield/Code/ContactedWebApp/venv/lib/python3.10/site-packages/flask/app.py", line 1825, in full_dispatch_request
    rv = self.handle_user_exception(e)
  File "/Users/lusarsfield/Code/ContactedWebApp/venv/lib/python3.10/site-packages/flask/app.py", line 1823, in full_dispatch_request
    rv = self.dispatch_request()
  File "/Users/lusarsfield/Code/ContactedWebApp/venv/lib/python3.10/site-packages/flask/app.py", line 1799, in dispatch_request
    return self.ensure_sync(self.view_functions[rule.endpoint])(**view_args)
  File "/Users/lusarsfield/Code/ContactedWebApp/venv/lib/python3.10/site-packages/flask_login/utils.py", line 290, in decorated_view
    return current_app.ensure_sync(func)(*args, **kwargs)
  File "/Users/lusarsfield/Code/ContactedWebApp/app/routes.py", line 211, in contacts
    users = user.query.all()
AttributeError: 'function' object has no attribute 'query'
2023-04-26 14:03:20,634 ERROR: Exception on /contacts [GET] [in /Users/lusarsfield/Code/ContactedWebApp/venv/lib/python3.10/site-packages/flask/app.py:1744]
Traceback (most recent call last):
  File "/Users/lusarsfield/Code/ContactedWebApp/venv/lib/python3.10/site-packages/flask/app.py", line 2528, in wsgi_app
    response = self.full_dispatch_request()
  File "/Users/lusarsfield/Code/ContactedWebApp/venv/lib/python3.10/site-packages/flask/app.py", line 1825, in full_dispatch_request
    rv = self.handle_user_exception(e)
  File "/Users/lusarsfield/Code/ContactedWebApp/venv/lib/python3.10/site-packages/flask/app.py", line 1823, in full_dispatch_request
    rv = self.dispatch_request()
  File "/Users/lusarsfield/Code/ContactedWebApp/venv/lib/python3.10/site-packages/flask/app.py", line 1799, in dispatch_request
    return self.ensure_sync(self.view_functions[rule.endpoint])(**view_args)
  File "/Users/lusarsfield/Code/ContactedWebApp/venv/lib/python3.10/site-packages/flask_login/utils.py", line 290, in decorated_view
    return current_app.ensure_sync(func)(*args, **kwargs)
  File "/Users/lusarsfield/Code/ContactedWebApp/app/routes.py", line 211, in contacts
    users = user.query.all()
AttributeError: 'function' object has no attribute 'query'
