2023-03-13 16:44:02,179 INFO: Microblog startup [in /Users/lusarsfield/Code/ContactedWebApp/app/__init__.py:47]
2023-03-13 16:44:09,282 ERROR: Exception on /login [POST] [in /Users/lusarsfield/Code/ContactedWebApp/venv/lib/python3.10/site-packages/flask/app.py:1744]
Traceback (most recent call last):
  File "/Users/lusarsfield/Code/ContactedWebApp/venv/lib/python3.10/site-packages/sqlalchemy/engine/base.py", line 1964, in _exec_single_context
    self.dialect.do_execute(
  File "/Users/lusarsfield/Code/ContactedWebApp/venv/lib/python3.10/site-packages/sqlalchemy/engine/default.py", line 748, in do_execute
    cursor.execute(statement, parameters)
sqlite3.OperationalError: no such table: user

The above exception was the direct cause of the following exception:

Traceback (most recent call last):
  File "/Users/lusarsfield/Code/ContactedWebApp/venv/lib/python3.10/site-packages/flask/app.py", line 2528, in wsgi_app
    response = self.full_dispatch_request()
  File "/Users/lusarsfield/Code/ContactedWebApp/venv/lib/python3.10/site-packages/flask/app.py", line 1825, in full_dispatch_request
    rv = self.handle_user_exception(e)
  File "/Users/lusarsfield/Code/ContactedWebApp/venv/lib/python3.10/site-packages/flask/app.py", line 1823, in full_dispatch_request
    rv = self.dispatch_request()
  File "/Users/lusarsfield/Code/ContactedWebApp/venv/lib/python3.10/site-packages/flask/app.py", line 1799, in dispatch_request
    return self.ensure_sync(self.view_functions[rule.endpoint])(**view_args)
  File "/Users/lusarsfield/Code/ContactedWebApp/app/routes.py", line 62, in login
    user = User.query.filter_by(username=form.username.data).first()
  File "/Users/lusarsfield/Code/ContactedWebApp/venv/lib/python3.10/site-packages/sqlalchemy/orm/query.py", line 2752, in first
    return self.limit(1)._iter().first()  # type: ignore
  File "/Users/lusarsfield/Code/ContactedWebApp/venv/lib/python3.10/site-packages/sqlalchemy/orm/query.py", line 2855, in _iter
    result: Union[ScalarResult[_T], Result[_T]] = self.session.execute(
  File "/Users/lusarsfield/Code/ContactedWebApp/venv/lib/python3.10/site-packages/sqlalchemy/orm/session.py", line 2229, in execute
    return self._execute_internal(
  File "/Users/lusarsfield/Code/ContactedWebApp/venv/lib/python3.10/site-packages/sqlalchemy/orm/session.py", line 2124, in _execute_internal
    result: Result[Any] = compile_state_cls.orm_execute_statement(
  File "/Users/lusarsfield/Code/ContactedWebApp/venv/lib/python3.10/site-packages/sqlalchemy/orm/context.py", line 253, in orm_execute_statement
    result = conn.execute(
  File "/Users/lusarsfield/Code/ContactedWebApp/venv/lib/python3.10/site-packages/sqlalchemy/engine/base.py", line 1414, in execute
    return meth(
  File "/Users/lusarsfield/Code/ContactedWebApp/venv/lib/python3.10/site-packages/sqlalchemy/sql/elements.py", line 486, in _execute_on_connection
    return connection._execute_clauseelement(
  File "/Users/lusarsfield/Code/ContactedWebApp/venv/lib/python3.10/site-packages/sqlalchemy/engine/base.py", line 1638, in _execute_clauseelement
    ret = self._execute_context(
  File "/Users/lusarsfield/Code/ContactedWebApp/venv/lib/python3.10/site-packages/sqlalchemy/engine/base.py", line 1842, in _execute_context
    return self._exec_single_context(
  File "/Users/lusarsfield/Code/ContactedWebApp/venv/lib/python3.10/site-packages/sqlalchemy/engine/base.py", line 1983, in _exec_single_context
    self._handle_dbapi_exception(
  File "/Users/lusarsfield/Code/ContactedWebApp/venv/lib/python3.10/site-packages/sqlalchemy/engine/base.py", line 2326, in _handle_dbapi_exception
    raise sqlalchemy_exception.with_traceback(exc_info[2]) from e
  File "/Users/lusarsfield/Code/ContactedWebApp/venv/lib/python3.10/site-packages/sqlalchemy/engine/base.py", line 1964, in _exec_single_context
    self.dialect.do_execute(
  File "/Users/lusarsfield/Code/ContactedWebApp/venv/lib/python3.10/site-packages/sqlalchemy/engine/default.py", line 748, in do_execute
    cursor.execute(statement, parameters)
sqlalchemy.exc.OperationalError: (sqlite3.OperationalError) no such table: user
[SQL: SELECT user.id AS user_id, user.username AS user_username, user.email AS user_email, user.password_hash AS user_password_hash, user.about_me AS user_about_me, user.last_seen AS user_last_seen 
FROM user 
WHERE user.username = ?
 LIMIT ? OFFSET ?]
[parameters: ('ls', 1, 0)]
(Background on this error at: https://sqlalche.me/e/20/e3q8)
2023-03-13 16:44:21,559 ERROR: Exception on /register [POST] [in /Users/lusarsfield/Code/ContactedWebApp/venv/lib/python3.10/site-packages/flask/app.py:1744]
Traceback (most recent call last):
  File "/Users/lusarsfield/Code/ContactedWebApp/venv/lib/python3.10/site-packages/sqlalchemy/engine/base.py", line 1964, in _exec_single_context
    self.dialect.do_execute(
  File "/Users/lusarsfield/Code/ContactedWebApp/venv/lib/python3.10/site-packages/sqlalchemy/engine/default.py", line 748, in do_execute
    cursor.execute(statement, parameters)
sqlite3.OperationalError: no such table: user

The above exception was the direct cause of the following exception:

Traceback (most recent call last):
  File "/Users/lusarsfield/Code/ContactedWebApp/venv/lib/python3.10/site-packages/flask/app.py", line 2528, in wsgi_app
    response = self.full_dispatch_request()
  File "/Users/lusarsfield/Code/ContactedWebApp/venv/lib/python3.10/site-packages/flask/app.py", line 1825, in full_dispatch_request
    rv = self.handle_user_exception(e)
  File "/Users/lusarsfield/Code/ContactedWebApp/venv/lib/python3.10/site-packages/flask/app.py", line 1823, in full_dispatch_request
    rv = self.dispatch_request()
  File "/Users/lusarsfield/Code/ContactedWebApp/venv/lib/python3.10/site-packages/flask/app.py", line 1799, in dispatch_request
    return self.ensure_sync(self.view_functions[rule.endpoint])(**view_args)
  File "/Users/lusarsfield/Code/ContactedWebApp/app/routes.py", line 85, in register
    if form.validate_on_submit():
  File "/Users/lusarsfield/Code/ContactedWebApp/venv/lib/python3.10/site-packages/flask_wtf/form.py", line 86, in validate_on_submit
    return self.is_submitted() and self.validate(extra_validators=extra_validators)
  File "/Users/lusarsfield/Code/ContactedWebApp/venv/lib/python3.10/site-packages/wtforms/form.py", line 329, in validate
    return super().validate(extra)
  File "/Users/lusarsfield/Code/ContactedWebApp/venv/lib/python3.10/site-packages/wtforms/form.py", line 146, in validate
    if not field.validate(self, extra):
  File "/Users/lusarsfield/Code/ContactedWebApp/venv/lib/python3.10/site-packages/wtforms/fields/core.py", line 242, in validate
    stop_validation = self._run_validation_chain(form, chain)
  File "/Users/lusarsfield/Code/ContactedWebApp/venv/lib/python3.10/site-packages/wtforms/fields/core.py", line 262, in _run_validation_chain
    validator(form, self)
  File "/Users/lusarsfield/Code/ContactedWebApp/app/forms.py", line 25, in validate_username
    user = User.query.filter_by(username=username.data).first()
  File "/Users/lusarsfield/Code/ContactedWebApp/venv/lib/python3.10/site-packages/sqlalchemy/orm/query.py", line 2752, in first
    return self.limit(1)._iter().first()  # type: ignore
  File "/Users/lusarsfield/Code/ContactedWebApp/venv/lib/python3.10/site-packages/sqlalchemy/orm/query.py", line 2855, in _iter
    result: Union[ScalarResult[_T], Result[_T]] = self.session.execute(
  File "/Users/lusarsfield/Code/ContactedWebApp/venv/lib/python3.10/site-packages/sqlalchemy/orm/session.py", line 2229, in execute
    return self._execute_internal(
  File "/Users/lusarsfield/Code/ContactedWebApp/venv/lib/python3.10/site-packages/sqlalchemy/orm/session.py", line 2124, in _execute_internal
    result: Result[Any] = compile_state_cls.orm_execute_statement(
  File "/Users/lusarsfield/Code/ContactedWebApp/venv/lib/python3.10/site-packages/sqlalchemy/orm/context.py", line 253, in orm_execute_statement
    result = conn.execute(
  File "/Users/lusarsfield/Code/ContactedWebApp/venv/lib/python3.10/site-packages/sqlalchemy/engine/base.py", line 1414, in execute
    return meth(
  File "/Users/lusarsfield/Code/ContactedWebApp/venv/lib/python3.10/site-packages/sqlalchemy/sql/elements.py", line 486, in _execute_on_connection
    return connection._execute_clauseelement(
  File "/Users/lusarsfield/Code/ContactedWebApp/venv/lib/python3.10/site-packages/sqlalchemy/engine/base.py", line 1638, in _execute_clauseelement
    ret = self._execute_context(
  File "/Users/lusarsfield/Code/ContactedWebApp/venv/lib/python3.10/site-packages/sqlalchemy/engine/base.py", line 1842, in _execute_context
    return self._exec_single_context(
  File "/Users/lusarsfield/Code/ContactedWebApp/venv/lib/python3.10/site-packages/sqlalchemy/engine/base.py", line 1983, in _exec_single_context
    self._handle_dbapi_exception(
  File "/Users/lusarsfield/Code/ContactedWebApp/venv/lib/python3.10/site-packages/sqlalchemy/engine/base.py", line 2326, in _handle_dbapi_exception
    raise sqlalchemy_exception.with_traceback(exc_info[2]) from e
  File "/Users/lusarsfield/Code/ContactedWebApp/venv/lib/python3.10/site-packages/sqlalchemy/engine/base.py", line 1964, in _exec_single_context
    self.dialect.do_execute(
  File "/Users/lusarsfield/Code/ContactedWebApp/venv/lib/python3.10/site-packages/sqlalchemy/engine/default.py", line 748, in do_execute
    cursor.execute(statement, parameters)
sqlalchemy.exc.OperationalError: (sqlite3.OperationalError) no such table: user
[SQL: SELECT user.id AS user_id, user.username AS user_username, user.email AS user_email, user.password_hash AS user_password_hash, user.about_me AS user_about_me, user.last_seen AS user_last_seen 
FROM user 
WHERE user.username = ?
 LIMIT ? OFFSET ?]
[parameters: ('smith', 1, 0)]
(Background on this error at: https://sqlalche.me/e/20/e3q8)
