2023-05-09 09:27:02,448 ERROR: Exception on /create_event [POST] [in /Users/lusarsfield/Code/ContactedWebApp/venv/lib/python3.10/site-packages/flask/app.py:1744]
Traceback (most recent call last):
  File "/Users/lusarsfield/Code/ContactedWebApp/venv/lib/python3.10/site-packages/sqlalchemy/engine/base.py", line 1808, in _execute_context
    context = constructor(
  File "/Users/lusarsfield/Code/ContactedWebApp/venv/lib/python3.10/site-packages/sqlalchemy/engine/default.py", line 1262, in _init_compiled
    l_param: List[Any] = [
  File "/Users/lusarsfield/Code/ContactedWebApp/venv/lib/python3.10/site-packages/sqlalchemy/engine/default.py", line 1263, in <listcomp>
    flattened_processors[key](compiled_params[key])
  File "/Users/lusarsfield/Code/ContactedWebApp/venv/lib/python3.10/site-packages/sqlalchemy/dialects/sqlite/base.py", line 1155, in process
    raise TypeError(
TypeError: SQLite Date type only accepts Python date objects as input.

The above exception was the direct cause of the following exception:

Traceback (most recent call last):
  File "/Users/lusarsfield/Code/ContactedWebApp/venv/lib/python3.10/site-packages/flask/app.py", line 2528, in wsgi_app
    response = self.full_dispatch_request()
  File "/Users/lusarsfield/Code/ContactedWebApp/venv/lib/python3.10/site-packages/flask/app.py", line 1825, in full_dispatch_request
    rv = self.handle_user_exception(e)
  File "/Users/lusarsfield/Code/ContactedWebApp/venv/lib/python3.10/site-packages/flask/app.py", line 1823, in full_dispatch_request
    rv = self.dispatch_request()
  File "/Users/lusarsfield/Code/ContactedWebApp/venv/lib/python3.10/site-packages/flask/app.py", line 1799, in dispatch_request
    return self.ensure_sync(self.view_functions[rule.endpoint])(**view_args)
  File "/Users/lusarsfield/Code/ContactedWebApp/venv/lib/python3.10/site-packages/flask_login/utils.py", line 290, in decorated_view
    return current_app.ensure_sync(func)(*args, **kwargs)
  File "/Users/lusarsfield/Code/ContactedWebApp/app/routes.py", line 223, in create_event
    db.session.commit()
  File "/Users/lusarsfield/Code/ContactedWebApp/venv/lib/python3.10/site-packages/sqlalchemy/orm/scoping.py", line 553, in commit
    return self._proxied.commit()
  File "/Users/lusarsfield/Code/ContactedWebApp/venv/lib/python3.10/site-packages/sqlalchemy/orm/session.py", line 1903, in commit
    trans.commit(_to_root=True)
  File "<string>", line 2, in commit
  File "/Users/lusarsfield/Code/ContactedWebApp/venv/lib/python3.10/site-packages/sqlalchemy/orm/state_changes.py", line 137, in _go
    ret_value = fn(self, *arg, **kw)
  File "/Users/lusarsfield/Code/ContactedWebApp/venv/lib/python3.10/site-packages/sqlalchemy/orm/session.py", line 1218, in commit
    self._prepare_impl()
  File "<string>", line 2, in _prepare_impl
  File "/Users/lusarsfield/Code/ContactedWebApp/venv/lib/python3.10/site-packages/sqlalchemy/orm/state_changes.py", line 137, in _go
    ret_value = fn(self, *arg, **kw)
  File "/Users/lusarsfield/Code/ContactedWebApp/venv/lib/python3.10/site-packages/sqlalchemy/orm/session.py", line 1193, in _prepare_impl
    self.session.flush()
  File "/Users/lusarsfield/Code/ContactedWebApp/venv/lib/python3.10/site-packages/sqlalchemy/orm/session.py", line 4155, in flush
    self._flush(objects)
  File "/Users/lusarsfield/Code/ContactedWebApp/venv/lib/python3.10/site-packages/sqlalchemy/orm/session.py", line 4291, in _flush
    with util.safe_reraise():
  File "/Users/lusarsfield/Code/ContactedWebApp/venv/lib/python3.10/site-packages/sqlalchemy/util/langhelpers.py", line 147, in __exit__
    raise exc_value.with_traceback(exc_tb)
  File "/Users/lusarsfield/Code/ContactedWebApp/venv/lib/python3.10/site-packages/sqlalchemy/orm/session.py", line 4252, in _flush
    flush_context.execute()
  File "/Users/lusarsfield/Code/ContactedWebApp/venv/lib/python3.10/site-packages/sqlalchemy/orm/unitofwork.py", line 467, in execute
    rec.execute(self)
  File "/Users/lusarsfield/Code/ContactedWebApp/venv/lib/python3.10/site-packages/sqlalchemy/orm/unitofwork.py", line 644, in execute
    util.preloaded.orm_persistence.save_obj(
  File "/Users/lusarsfield/Code/ContactedWebApp/venv/lib/python3.10/site-packages/sqlalchemy/orm/persistence.py", line 93, in save_obj
    _emit_insert_statements(
  File "/Users/lusarsfield/Code/ContactedWebApp/venv/lib/python3.10/site-packages/sqlalchemy/orm/persistence.py", line 1184, in _emit_insert_statements
    result = connection.execute(
  File "/Users/lusarsfield/Code/ContactedWebApp/venv/lib/python3.10/site-packages/sqlalchemy/engine/base.py", line 1414, in execute
    return meth(
  File "/Users/lusarsfield/Code/ContactedWebApp/venv/lib/python3.10/site-packages/sqlalchemy/sql/elements.py", line 486, in _execute_on_connection
    return connection._execute_clauseelement(
  File "/Users/lusarsfield/Code/ContactedWebApp/venv/lib/python3.10/site-packages/sqlalchemy/engine/base.py", line 1638, in _execute_clauseelement
    ret = self._execute_context(
  File "/Users/lusarsfield/Code/ContactedWebApp/venv/lib/python3.10/site-packages/sqlalchemy/engine/base.py", line 1814, in _execute_context
    self._handle_dbapi_exception(
  File "/Users/lusarsfield/Code/ContactedWebApp/venv/lib/python3.10/site-packages/sqlalchemy/engine/base.py", line 2326, in _handle_dbapi_exception
    raise sqlalchemy_exception.with_traceback(exc_info[2]) from e
  File "/Users/lusarsfield/Code/ContactedWebApp/venv/lib/python3.10/site-packages/sqlalchemy/engine/base.py", line 1808, in _execute_context
    context = constructor(
  File "/Users/lusarsfield/Code/ContactedWebApp/venv/lib/python3.10/site-packages/sqlalchemy/engine/default.py", line 1262, in _init_compiled
    l_param: List[Any] = [
  File "/Users/lusarsfield/Code/ContactedWebApp/venv/lib/python3.10/site-packages/sqlalchemy/engine/default.py", line 1263, in <listcomp>
    flattened_processors[key](compiled_params[key])
  File "/Users/lusarsfield/Code/ContactedWebApp/venv/lib/python3.10/site-packages/sqlalchemy/dialects/sqlite/base.py", line 1155, in process
    raise TypeError(
sqlalchemy.exc.StatementError: (builtins.TypeError) SQLite Date type only accepts Python date objects as input.
[SQL: INSERT INTO event (user_id, eventname, eventadress, eventdate, eventtime, eventhost, eventcontact, eventdetails) VALUES (?, ?, ?, ?, ?, ?, ?, ?)]
[parameters: [{'eventtime': 'f', 'eventhost': 'f', 'user_id': 1, 'eventdate': 'f', 'eventdetails': 'f', 'eventadress': 'f', 'eventcontact': 'f', 'eventname': 'f'}]]
2023-05-09 09:28:31,551 INFO: Microblog startup [in /Users/lusarsfield/Code/ContactedWebApp/app/__init__.py:47]
2023-05-09 09:42:49,474 INFO: Microblog startup [in /Users/lusarsfield/Code/ContactedWebApp/app/__init__.py:47]
2023-05-09 09:43:28,948 INFO: Microblog startup [in /Users/lusarsfield/Code/ContactedWebApp/app/__init__.py:47]
2023-05-09 09:43:53,534 INFO: Microblog startup [in /Users/lusarsfield/Code/ContactedWebApp/app/__init__.py:47]
2023-05-09 09:44:31,839 INFO: Microblog startup [in /Users/lusarsfield/Code/ContactedWebApp/app/__init__.py:47]
2023-05-09 09:44:33,733 ERROR: Exception on /events [GET] [in /Users/lusarsfield/Code/ContactedWebApp/venv/lib/python3.10/site-packages/flask/app.py:1744]
Traceback (most recent call last):
  File "/Users/lusarsfield/Code/ContactedWebApp/venv/lib/python3.10/site-packages/flask/app.py", line 2528, in wsgi_app
    response = self.full_dispatch_request()
  File "/Users/lusarsfield/Code/ContactedWebApp/venv/lib/python3.10/site-packages/flask/app.py", line 1825, in full_dispatch_request
    rv = self.handle_user_exception(e)
  File "/Users/lusarsfield/Code/ContactedWebApp/venv/lib/python3.10/site-packages/flask/app.py", line 1823, in full_dispatch_request
    rv = self.dispatch_request()
  File "/Users/lusarsfield/Code/ContactedWebApp/venv/lib/python3.10/site-packages/flask/app.py", line 1799, in dispatch_request
    return self.ensure_sync(self.view_functions[rule.endpoint])(**view_args)
  File "/Users/lusarsfield/Code/ContactedWebApp/venv/lib/python3.10/site-packages/flask_login/utils.py", line 290, in decorated_view
    return current_app.ensure_sync(func)(*args, **kwargs)
  File "/Users/lusarsfield/Code/ContactedWebApp/app/routes.py", line 208, in events
    return render_template('events.html', events=events)
  File "/Users/lusarsfield/Code/ContactedWebApp/venv/lib/python3.10/site-packages/flask/templating.py", line 146, in render_template
    template = app.jinja_env.get_or_select_template(template_name_or_list)
  File "/Users/lusarsfield/Code/ContactedWebApp/venv/lib/python3.10/site-packages/jinja2/environment.py", line 1081, in get_or_select_template
    return self.get_template(template_name_or_list, parent, globals)
  File "/Users/lusarsfield/Code/ContactedWebApp/venv/lib/python3.10/site-packages/jinja2/environment.py", line 1010, in get_template
    return self._load_template(name, globals)
  File "/Users/lusarsfield/Code/ContactedWebApp/venv/lib/python3.10/site-packages/jinja2/environment.py", line 969, in _load_template
    template = self.loader.load(self, name, self.make_globals(globals))
  File "/Users/lusarsfield/Code/ContactedWebApp/venv/lib/python3.10/site-packages/jinja2/loaders.py", line 138, in load
    code = environment.compile(source, name, filename)
  File "/Users/lusarsfield/Code/ContactedWebApp/venv/lib/python3.10/site-packages/jinja2/environment.py", line 768, in compile
    self.handle_exception(source=source_hint)
  File "/Users/lusarsfield/Code/ContactedWebApp/venv/lib/python3.10/site-packages/jinja2/environment.py", line 936, in handle_exception
    raise rewrite_traceback_stack(source=source)
  File "/Users/lusarsfield/Code/ContactedWebApp/app/templates/events.html", line 31, in template
    <td>{{ <a href="{{ url_for('chat') }}" class= "btn btn-primary btn-block" role="button"> Open Chat </a> }}</td>
jinja2.exceptions.TemplateSyntaxError: unexpected '<'
2023-05-09 09:44:56,506 INFO: Microblog startup [in /Users/lusarsfield/Code/ContactedWebApp/app/__init__.py:47]
